<?xml version="1.0" ?>
<!-- =================================================================================== -->
<!-- |    This document was autogenerated by xacro from panda_arm.inertial.urdf.xacro  | -->
<!-- |    EDITING THIS FILE BY HAND IS NOT RECOMMENDED                                 | -->
<!-- =================================================================================== -->
<robot name="panda" xmlns:xacro="http://www.ros.org/wiki/xacro">
  <link name="world"/>
  <joint name="panda_joint_world" type="fixed">
    <parent link="world"/>
    <child link="panda_link0"/>
    <origin rpy="0 0 0" xyz="0 0 0"/>
  </joint>
  <link name="panda_link0">
    <inertial>
      <origin rpy="0 0 0" xyz="-0.0291898 -0.000879465 0.0566032"/>
      <mass value="3.01399"/>
      <inertia ixx="0.0126801" ixy="0" ixz="0" iyy="0.0117603" iyz="0" izz="0.00856656"/>
    </inertial>
    <visual>
      <geometry>
        <mesh filename="../meshes/visual/link0.dae"/>
      </geometry>
      <material name="panda_white"/>
    </visual>
    <collision>
      <geometry>
        <mesh filename="../meshes/collision/link0.stl"/>
      </geometry>
      <material name="panda_white"/>
    </collision>
  </link>
  <link name="panda_link1">
    <inertial>
      <origin rpy="0 0 0" xyz="1.1399e-05 -0.0312655 -0.0693733"/>
      <mass value="2.77281"/>
      <inertia ixx="0.0164224" ixy="0" ixz="0" iyy="0.0153969" iyz="0" izz="0.00546286"/>
    </inertial>
    <visual>
      <geometry>
        <mesh filename="../meshes/visual/link1.dae"/>
      </geometry>
      <material name="panda_white"/>
    </visual>
    <collision>
      <geometry>
        <mesh filename="../meshes/collision/link1.stl"/>
      </geometry>
      <material name="panda_white"/>
    </collision>
  </link>
  <joint name="panda_joint1" type="revolute">
    <safety_controller k_position="100.0" k_velocity="40.0" soft_lower_limit="-2.8973" soft_upper_limit="2.8973"/>
    <origin rpy="0 0 0" xyz="0 0 0.333"/>
    <parent link="panda_link0"/>
    <child link="panda_link1"/>
    <axis xyz="0 0 1"/>
    <limit effort="87" lower="-2.9671" upper="2.9671" velocity="2.3925"/>
  </joint>
  <link name="panda_link2">
    <inertial>
      <origin rpy="0 0 0" xyz="-1.31766e-05 -0.0703216 0.0311782"/>
      <mass value="2.7996"/>
      <inertia ixx="0.016787" ixy="0" ixz="0" iyy="0.0157415" iyz="0" izz="0.00553027"/>
    </inertial>
    <visual>
      <geometry>
        <mesh filename="../meshes/visual/link2.dae"/>
      </geometry>
      <material name="panda_white"/>
    </visual>
    <collision>
      <geometry>
        <mesh filename="../meshes/collision/link2.stl"/>
      </geometry>
      <material name="panda_white"/>
    </collision>
  </link>
  <joint name="panda_joint2" type="revolute">
    <safety_controller k_position="100.0" k_velocity="40.0" soft_lower_limit="-1.7628" soft_upper_limit="1.7628"/>
    <origin rpy="-1.57079632679 0 0" xyz="0 0 0"/>
    <parent link="panda_link1"/>
    <child link="panda_link2"/>
    <axis xyz="0 0 1"/>
    <limit effort="87" lower="-1.8326" upper="1.8326" velocity="2.3925"/>
  </joint>
  <link name="panda_link3">
    <inertial>
      <origin rpy="0 0 0" xyz="0.0443483 0.0249283 -0.03813"/>
      <mass value="2.14603"/>
      <inertia ixx="0.00915257" ixy="0" ixz="0" iyy="0.00896477" iyz="0" izz="0.00384742"/>
    </inertial>
    <visual>
      <geometry>
        <mesh filename="../meshes/visual/link3.dae"/>
      </geometry>
      <material name="panda_white"/>
    </visual>
    <collision>
      <geometry>
        <mesh filename="../meshes/collision/link3.stl"/>
      </geometry>
      <material name="panda_white"/>
    </collision>
  </link>
  <joint name="panda_joint3" type="revolute">
    <safety_controller k_position="100.0" k_velocity="40.0" soft_lower_limit="-2.8973" soft_upper_limit="2.8973"/>
    <origin rpy="1.57079632679 0 0" xyz="0 -0.316 0"/>
    <parent link="panda_link2"/>
    <child link="panda_link3"/>
    <axis xyz="0 0 1"/>
    <limit effort="87" lower="-2.9671" upper="2.9671" velocity="2.3925"/>
  </joint>
  <link name="panda_link4">
    <inertial>
      <origin rpy="0 0 0" xyz="-0.0385503 0.0395256 0.0247162"/>
      <mass value="2.18807"/>
      <inertia ixx="0.00946899" ixy="0" ixz="0" iyy="0.00928491" iyz="0" izz="0.00396694"/>
    </inertial>
    <visual>
      <geometry>
        <mesh filename="../meshes/visual/link4.dae"/>
      </geometry>
      <material name="panda_white"/>
    </visual>
    <collision>
      <geometry>
        <mesh filename="../meshes/collision/link4.stl"/>
      </geometry>
      <material name="panda_white"/>
    </collision>
  </link>
  <joint name="panda_joint4" type="revolute">
    <safety_controller k_position="100.0" k_velocity="40.0" soft_lower_limit="-3.0718" soft_upper_limit="0.0175"/>
    <origin rpy="1.57079632679 0 0" xyz="0.0825 0 0"/>
    <parent link="panda_link3"/>
    <child link="panda_link4"/>
    <axis xyz="0 0 1"/>
    <limit effort="87" lower="-3.1416" upper="0.0873" velocity="2.3925"/>
  </joint>
  <link name="panda_link5">
    <inertial>
      <origin rpy="0 0 0" xyz="-6.36776e-05 0.0384124 -0.10997"/>
      <mass value="3.19545"/>
      <inertia ixx="0.0278873" ixy="0" ixz="0" iyy="0.0268823" iyz="0" izz="0.00569569"/>
    </inertial>
    <visual>
      <geometry>
        <mesh filename="../meshes/visual/link5.dae"/>
      </geometry>
      <material name="panda_white"/>
    </visual>
    <collision>
      <geometry>
        <mesh filename="../meshes/collision/link5.stl"/>
      </geometry>
      <material name="panda_white"/>
    </collision>
  </link>
  <joint name="panda_joint5" type="revolute">
    <safety_controller k_position="100.0" k_velocity="40.0" soft_lower_limit="-2.8973" soft_upper_limit="2.8973"/>
    <origin rpy="-1.57079632679 0 0" xyz="-0.0825 0.384 0"/>
    <parent link="panda_link4"/>
    <child link="panda_link5"/>
    <axis xyz="0 0 1"/>
    <limit effort="12" lower="-2.9671" upper="2.9671" velocity="2.8710"/>
  </joint>
  <link name="panda_link6">
    <inertial>
      <origin rpy="0 0 0" xyz="0.0510023 0.00693267 0.00616899"/>
      <mass value="1.35761"/>
      <inertia ixx="0.00412168" ixy="0" ixz="0" iyy="0.0033698" iyz="0" izz="0.00213304"/>
    </inertial>
    <visual>
      <geometry>
        <mesh filename="../meshes/visual/link6.dae"/>
      </geometry>
      <material name="panda_white"/>
    </visual>
    <collision>
      <geometry>
        <mesh filename="../meshes/collision/link6.stl"/>
      </geometry>
      <material name="panda_white"/>
    </collision>
  </link>
  <joint name="panda_joint6" type="revolute">
    <safety_controller k_position="100.0" k_velocity="40.0" soft_lower_limit="-0.0175" soft_upper_limit="3.7525"/>
    <origin rpy="1.57079632679 0 0" xyz="0 0 0"/>
    <parent link="panda_link5"/>
    <child link="panda_link6"/>
    <axis xyz="0 0 1"/>
    <limit effort="12" lower="-0.0873" upper="3.8223" velocity="2.8710"/>
  </joint>
  <link name="panda_link7">
    <inertial>
      <origin rpy="0 0 0" xyz="0.0103614 0.0103596 0.0791078"/>
      <mass value="0.417345"/>
      <inertia ixx="0.000637671" ixy="0." ixz="0" iyy="0.000528056" iyz="0" izz="0.000279577"/>
    </inertial>
    <visual>
      <geometry>
        <mesh filename="../meshes/visual/link7.dae"/>
      </geometry>
      <material name="panda_white"/>
    </visual>
    <collision>
      <geometry>
        <mesh filename="../meshes/collision/link7.stl"/>
      </geometry>
      <material name="panda_white"/>
    </collision>
  </link>
  <joint name="panda_joint7" type="revolute">
    <safety_controller k_position="100.0" k_velocity="40.0" soft_lower_limit="-2.8973" soft_upper_limit="2.8973"/>
    <origin rpy="1.57079632679 0 0" xyz="0.088 0 0"/>
    <parent link="panda_link6"/>
    <child link="panda_link7"/>
    <axis xyz="0 0 1"/>
    <limit effort="12" lower="-2.9671" upper="2.9671" velocity="2.8710"/>
  </joint>
  <link name="panda_link8">
    <inertial>
      <origin rpy="0 0 0" xyz="-0.0 0 0.107"/>
      <mass value=".1"/>
      <inertia ixx="0.1" ixy="0" ixz="0" iyy="0.1" iyz="0" izz="0.1"/>
    </inertial>
  </link>
  <joint name="panda_joint8" type="fixed">
    <origin rpy="0 0 0" xyz="0 0 0.107"/>
    <parent link="panda_link7"/>
    <child link="panda_link8"/>
    <axis xyz="0 0 0"/>
  </joint>

  <!-- PANDA HAND -->
  <joint name="panda_hand_joint" type="fixed">
    <parent link="panda_link8"/>
    <child link="panda_hand"/>
    <origin rpy="0 0 -0.785398163397" xyz="0 0 0"/>
  </joint>

  <link name="panda_hand">
	<inertial>
      <origin rpy="0 0 0" xyz="-2.76618e-06 -0.00061547 0.0239295"/>
      <mass value="0.670782"/>
      <inertia ixx="0.00227632" ixy="0" ixz="0" iyy="0.00206087" iyz="0" izz="0.000456542"/>
    </inertial>
    <visual>
      <geometry>
        <mesh filename="../meshes/visual/hand.dae"/>
      </geometry>
    </visual>
    <collision>
      <geometry>
        <mesh filename="../meshes/collision/hand.stl"/>
      </geometry>
    </collision>
  </link>
  <link name="panda_leftfinger">
	<inertial>
      <origin rpy="0 0 0" xyz="-2.42335e-05 0.0119585 0.0237816"/>
      <mass value="0.0218754"/>
      <inertia ixx="5.69661e-06" ixy="0" ixz="0" iyy="5.56035e-06" iyz="0" izz="1.55183e-06"/>
    </inertial>
    <visual>
      <geometry>
        <mesh filename="../meshes/visual/finger.dae"/>
      </geometry>
    </visual>
    <collision>
      <geometry>
        <mesh filename="../meshes/collision/finger.stl"/>
      </geometry>
    </collision>
  </link>
  <link name="panda_rightfinger">
	<inertial>
      <origin rpy="0 0 0" xyz="2.42335e-05 -0.0119585 0.0237816"/>
      <mass value="0.0218754"/>
      <inertia ixx="5.69661e-06" ixy="0" ixz="0" iyy="5.56035e-06" iyz="0" izz="1.55183e-06"/>
    </inertial>
    <visual>
      <origin rpy="0 0 3.14159265359" xyz="0 0 0"/>
      <geometry>
        <mesh filename="../meshes/visual/finger.dae"/>
      </geometry>
    </visual>
    <collision>
      <origin rpy="0 0 3.14159265359" xyz="0 0 0"/>
      <geometry>
        <mesh filename="../meshes/collision/finger.stl"/>
      </geometry>
    </collision>
  </link>
  <joint name="panda_finger_joint1" type="prismatic">
    <parent link="panda_hand"/>
    <child link="panda_leftfinger"/>
    <origin rpy="0 0 0" xyz="0 0 0.0584"/>
    <axis xyz="0 1 0"/>
    <limit effort="20" lower="0.0" upper="0.04" velocity="0.2"/>
  </joint>
  <joint name="panda_finger_joint2" type="prismatic">
    <parent link="panda_hand"/>
    <child link="panda_rightfinger"/>
    <origin rpy="0 0 0" xyz="0 0 0.0584"/>
    <axis xyz="0 -1 0"/>
    <limit effort="20" lower="0.0" upper="0.04" velocity="0.2"/>
    <mimic joint="panda_finger_joint1"/>
  </joint>
  


  <!-- MATERIALS -->
  <material name="panda_white">
    <color rgba="1. 1. 1. 1."/>
  </material>
  <material name="aluminum">
    <color rgba="0.5 0.5 0.5 1"/>
  </material>  
</robot>

 
